Task ansible_ui.tasks.execute_playbook_using_command[2fc81494-346b-4696-a4a1-f0ea5d523268] raised unexpected: TypeError("'int' object is not callable",)
Traceback (most recent call last):
  File "/Users/guang/.virtualenvs/ansible/lib/python3.6/site-packages/celery/app/trace.py", line 382, in trace_task
    R = retval = fun(*args, **kwargs)
  File "/Users/guang/.virtualenvs/ansible/lib/python3.6/site-packages/celery/app/trace.py", line 641, in __protected_call__
    return self.run(*args, **kwargs)
  File "/Users/guang/projects/AnsibleUI/ansible_ui/tasks.py", line 33, in execute_playbook_using_command
    return playbook.execute_using_command(save_history=save_history)
  File "/Users/guang/projects/AnsibleUI/ansible_ui/models/playbook.py", line 213, in execute_using_command
    ], stdout=sys.stdout, stderr=sys.stderr)
  File "/Library/Frameworks/Python.framework/Versions/3.6/lib/python3.6/subprocess.py", line 665, in __init__
    errread, errwrite) = self._get_handles(stdin, stdout, stderr)
  File "/Library/Frameworks/Python.framework/Versions/3.6/lib/python3.6/subprocess.py", line 1174, in _get_handles
    c2pwrite = stdout.fileno()
TypeError: 'int' object is not callable
